Workbook

Sheet Feuille de route
A1: Feuille de route MCU1 : réécriture des drivers STM32 en C++
A2: Cours Udemy « Mastering Microcontroller and Embedded Driver Development » (FastBit Embedded Brain Academy, Kiran Nayak)
A3: Hypothèses du plan
A4: Rythme : 5 jours par semaine (lundi au vendredi), 30 min de vidéo puis 1 h 30 de code.
A5: Pause de Noël du 21/12/2026 au 01/01/2027, semaine allégée du 18 au 22/01/2027, partiels du 25/01 au 05/02/2027 (dates supposées, à corriger dans « Plan quotidien »).
A6: Les dates sont des cibles : elles peuvent glisser de 3 à 4 semaines sans remettre le plan en cause.
A7: Les jours « Code seul » sont ceux où la vidéo est finie et où tu construis la brique du projet (GPS, carte SD, IMU).
A8: Avancement global (J0 à J3) | B8: =IF(SUM(I11:I14)=0,"",SUM(J11:J14)/SUM(I11:I14)) -> 0
A10: Jalon | B10: Chapitres du cours | C10: Vidéo (min) | D10: Vidéo (h min) | E10: Ce que tu construis en C++ | F10: Validé quand | G10: Début | H10: Fin | I10: Jours prévus | J10: Jours complets | K10: Avancement | L10: Statut | M10: Cible hors calendrier
A11: J0 Fondations | B11: Intro, débogage, mémoire, bus, horloges, vecteurs et NVIC, GPIO complet, EXTI | C11: =SUMIFS(Leçons!$E$5:$E$289,Leçons!$B$5:$B$289,A11) -> 703.4 | D11: =IF(C11=0,"",INT(ROUND(C11,0)/60)&" h "&TEXT(MOD(ROUND(C11,0),60),"00")) -> 11 h 43 | E11: Classes Rcc et Gpio, bouton en interruption | F11: Tu expliques chaque ligne, LED et bouton fonctionnent | G11: =IF(I11=0,"—",_xlfn.MINIFS('Plan quotidien'!$A$6:$A$104,'Plan quotidien'!$B$6:$B$104,A11)) -> 46307 | H11: =IF(I11=0,"—",_xlfn.MAXIFS('Plan quotidien'!$A$6:$A$104,'Plan quotidien'!$B$6:$B$104,A11)) -> 46338 | I11: =COUNTIF('Plan quotidien'!$B$6:$B$104,A11) -> 24 | J11: =COUNTIFS('Plan quotidien'!$B$6:$B$104,A11,'Plan quotidien'!$K$6:$K$104,"Oui") -> 0 | K11: =IF(I11=0,"",J11/I11) -> 0 | L11: =IF(I11=0,"À planifier",IF(J11>=I11,"Terminé",IF(J11>0,"En cours","À faire"))) -> À faire
A12: J1 GPS | B12: USART | C12: =SUMIFS(Leçons!$E$5:$E$289,Leçons!$B$5:$B$289,A12) -> 105.91 | D12: =IF(C12=0,"",INT(ROUND(C12,0)/60)&" h "&TEXT(MOD(ROUND(C12,0),60),"00")) -> 1 h 46 | E12: Classe Uart, parseur NMEA, position et vitesse en direct sur le PC | F12: Position fiable à l'extérieur, 10 Hz si le module le permet | G12: =IF(I12=0,"—",_xlfn.MINIFS('Plan quotidien'!$A$6:$A$104,'Plan quotidien'!$B$6:$B$104,A12)) -> 46339 | H12: =IF(I12=0,"—",_xlfn.MAXIFS('Plan quotidien'!$A$6:$A$104,'Plan quotidien'!$B$6:$B$104,A12)) -> 46353 | I12: =COUNTIF('Plan quotidien'!$B$6:$B$104,A12) -> 11 | J12: =COUNTIFS('Plan quotidien'!$B$6:$B$104,A12,'Plan quotidien'!$K$6:$K$104,"Oui") -> 0 | K12: =IF(I12=0,"",J12/I12) -> 0 | L12: =IF(I12=0,"À planifier",IF(J12>=I12,"Terminé",IF(J12>0,"En cours","À faire"))) -> À faire
A13: J2 Carte SD | B13: SPI complet | C13: =SUMIFS(Leçons!$E$5:$E$289,Leçons!$B$5:$B$289,A13) -> 318.12 | D13: =IF(C13=0,"",INT(ROUND(C13,0)/60)&" h "&TEXT(MOD(ROUND(C13,0),60),"00")) -> 5 h 18 | E13: Classe Spi, écriture SD avec FatFs, trames GPS en CSV | F13: Un CSV propre après coupure, fichier fermé correctement | G13: =IF(I13=0,"—",_xlfn.MINIFS('Plan quotidien'!$A$6:$A$104,'Plan quotidien'!$B$6:$B$104,A13)) -> 46356 | H13: =IF(I13=0,"—",_xlfn.MAXIFS('Plan quotidien'!$A$6:$A$104,'Plan quotidien'!$B$6:$B$104,A13)) -> 46402 | I13: =COUNTIF('Plan quotidien'!$B$6:$B$104,A13) -> 25 | J13: =COUNTIFS('Plan quotidien'!$B$6:$B$104,A13,'Plan quotidien'!$K$6:$K$104,"Oui") -> 0 | K13: =IF(I13=0,"",J13/I13) -> 0 | L13: =IF(I13=0,"À planifier",IF(J13>=I13,"Terminé",IF(J13>0,"En cours","À faire"))) -> À faire
A14: J3 IMU | B14: I2C maître : théorie, init, envoi, réception | C14: =SUMIFS(Leçons!$E$5:$E$289,Leçons!$B$5:$B$289,A14) -> 250.88 | D14: =IF(C14=0,"",INT(ROUND(C14,0)/60)&" h "&TEXT(MOD(ROUND(C14,0),60),"00")) -> 4 h 11 | E14: Classe I2c, lecture de l'accéléromètre, filtrage, calibration | F14: G latéral et longitudinal stables, offset corrigé au repos | G14: =IF(I14=0,"—",_xlfn.MINIFS('Plan quotidien'!$A$6:$A$104,'Plan quotidien'!$B$6:$B$104,A14)) -> 46426 | H14: =IF(I14=0,"—",_xlfn.MAXIFS('Plan quotidien'!$A$6:$A$104,'Plan quotidien'!$B$6:$B$104,A14)) -> 46443 | I14: =COUNTIF('Plan quotidien'!$B$6:$B$104,A14) -> 14 | J14: =COUNTIFS('Plan quotidien'!$B$6:$B$104,A14,'Plan quotidien'!$K$6:$K$104,"Oui") -> 0 | K14: =IF(I14=0,"",J14/I14) -> 0 | L14: =IF(I14=0,"À planifier",IF(J14>=I14,"Terminé",IF(J14>0,"En cours","À faire"))) -> À faire
A15: J4 Fusion + visualisation | B15: SysTick (fin du dernier chapitre) | C15: =SUMIFS(Leçons!$E$5:$E$289,Leçons!$B$5:$B$289,A15) -> 12.57 | D15: =IF(C15=0,"",INT(ROUND(C15,0)/60)&" h "&TEXT(MOD(ROUND(C15,0),60),"00")) -> 0 h 13 | E15: Horodatage commun, CSV GPS + IMU, Python : tracé coloré, courbes, deux tours superposés | F15: L'image d'un tour avec accélérations et freinages | G15: =IF(I15=0,"—",_xlfn.MINIFS('Plan quotidien'!$A$6:$A$104,'Plan quotidien'!$B$6:$B$104,A15)) -> — | H15: =IF(I15=0,"—",_xlfn.MAXIFS('Plan quotidien'!$A$6:$A$104,'Plan quotidien'!$B$6:$B$104,A15)) -> — | I15: =COUNTIF('Plan quotidien'!$B$6:$B$104,A15) -> 0 | J15: =COUNTIFS('Plan quotidien'!$B$6:$B$104,A15,'Plan quotidien'!$K$6:$K$104,"Oui") -> 0 | K15: =IF(I15=0,"",J15/I15) | L15: =IF(I15=0,"À planifier",IF(J15>=I15,"Terminé",IF(J15>0,"En cours","À faire"))) -> À planifier | M15: mars-avril, rythme à recaler avec le stage
A16: J5 Test réel | C16: =SUMIFS(Leçons!$E$5:$E$289,Leçons!$B$5:$B$289,A16) -> 0 | D16: =IF(C16=0,"",INT(ROUND(C16,0)/60)&" h "&TEXT(MOD(ROUND(C16,0),60),"00")) | E16: Montage fixé, alimentation stable, premier roulage prudent | F16: Un vrai tour enregistré dans la Mégane | G16: =IF(I16=0,"—",_xlfn.MINIFS('Plan quotidien'!$A$6:$A$104,'Plan quotidien'!$B$6:$B$104,A16)) -> — | H16: =IF(I16=0,"—",_xlfn.MAXIFS('Plan quotidien'!$A$6:$A$104,'Plan quotidien'!$B$6:$B$104,A16)) -> — | I16: =COUNTIF('Plan quotidien'!$B$6:$B$104,A16) -> 0 | J16: =COUNTIFS('Plan quotidien'!$B$6:$B$104,A16,'Plan quotidien'!$K$6:$K$104,"Oui") -> 0 | K16: =IF(I16=0,"",J16/I16) | L16: =IF(I16=0,"À planifier",IF(J16>=I16,"Terminé",IF(J16>0,"En cours","À faire"))) -> À planifier | M16: été 2027
A17: Phase 2 CAN | B17: Cours MCU2 (CAN), si tu le prends | C17: =SUMIFS(Leçons!$E$5:$E$289,Leçons!$B$5:$B$289,A17) -> 0 | D17: =IF(C17=0,"",INT(ROUND(C17,0)/60)&" h "&TEXT(MOD(ROUND(C17,0),60),"00")) | E17: Lecture seule du bus CAN | F17: Données moteur synchronisées avec GPS et IMU | G17: =IF(I17=0,"—",_xlfn.MINIFS('Plan quotidien'!$A$6:$A$104,'Plan quotidien'!$B$6:$B$104,A17)) -> — | H17: =IF(I17=0,"—",_xlfn.MAXIFS('Plan quotidien'!$A$6:$A$104,'Plan quotidien'!$B$6:$B$104,A17)) -> — | I17: =COUNTIF('Plan quotidien'!$B$6:$B$104,A17) -> 0 | J17: =COUNTIFS('Plan quotidien'!$B$6:$B$104,A17,'Plan quotidien'!$K$6:$K$104,"Oui") -> 0 | K17: =IF(I17=0,"",J17/I17) | L17: =IF(I17=0,"À planifier",IF(J17>=I17,"Terminé",IF(J17>0,"En cours","À faire"))) -> À planifier | M17: après
A18: Facultatif | B18: I2C en interruption et esclave, RTC, LCD | C18: =SUMIFS(Leçons!$E$5:$E$289,Leçons!$B$5:$B$289,A18) -> 303.7 | D18: =IF(C18=0,"",INT(ROUND(C18,0)/60)&" h "&TEXT(MOD(ROUND(C18,0),60),"00")) -> 5 h 04 | E18: Pour aller plus loin, sans bloquer le projet | G18: =IF(I18=0,"—",_xlfn.MINIFS('Plan quotidien'!$A$6:$A$104,'Plan quotidien'!$B$6:$B$104,A18)) -> — | H18: =IF(I18=0,"—",_xlfn.MAXIFS('Plan quotidien'!$A$6:$A$104,'Plan quotidien'!$B$6:$B$104,A18)) -> — | I18: =COUNTIF('Plan quotidien'!$B$6:$B$104,A18) -> 0 | J18: =COUNTIFS('Plan quotidien'!$B$6:$B$104,A18,'Plan quotidien'!$K$6:$K$104,"Oui") -> 0 | K18: =IF(I18=0,"",J18/I18) | L18: Facultatif | M18: si le temps le permet
A19: Total vidéo | C19: =SUM(C11:C18) -> 1694.58 | D19: =INT(ROUND(C19,0)/60)&" h "&TEXT(MOD(ROUND(C19,0),60),"00") -> 28 h 15 | I19: =SUM(I11:I18) -> 74 | J19: =SUM(J11:J18) -> 0
A21: Réglages
A22: - Les timers ne sont pas dans MCU1 : pour l'horodatage, SysTick (millisecondes) suffit au début.
A23: - Le GPS ne demande que l'USART : c'est pour cela qu'il passe avant le SPI et l'I2C.
A24: - La carte SD suit le SPI, l'IMU suit l'I2C : chaque chapitre est suivi de son application dans le système.
A25: - Si tu bloques plus d'une semaine sur une brique, tu peux utiliser le HAL de ST pour elle seule, puis y revenir.
A26: - Le CAN et les timers avancés relèvent du cours MCU2 du même formateur, à décider une fois MCU1 terminé.

Sheet Plan quotidien
A1: Plan quotidien (30 min de vidéo + 1 h 30 de code)
A2: À remplir : colonnes H et I (liste Oui / Non), J (minutes de code) et L (notes). Les dates sont des cibles saisies à la main : modifie-les si tes partiels ou tes vacances bougent. La colonne « Complet » se calcule seule.
A4: Date | B4: Jalon | C4: Type de jour | D4: Vidéo à regarder | E4: Vidéo (min) | F4: Code du jour (1 h 30) | G4: Notion C++ à réviser | H4: Vidéo faite ? | I4: Code fait ? | J4: Minutes de code | K4: Complet | L4: Notes
A5: Exemple | B5: J0 Fondations | C5: Vidéo + code | D5: Understanding Memory Map of the MCU: Part 1 (5 min) | E5: 17 | F5: Réécrire en C++ : header avec les adresses de base de la carte mémoire (constexpr) | G5: constexpr, enum class | H5: Oui | I5: Oui | J5: 90 | K5: Oui | L5: Header écrit, il compile
A6: 46307 | B6: J0 Fondations | C6: Vidéo + code | D6: About the instructor (moins d'1 min) Important Note (moins d'1 min) What is this course all about ?? (6 min) Source Code and Slides (moins d'1 min) Rating and Review (moins d'1 min) About MCU Development board (3 min) Hardware/Software Requirements (moins d'1 min) Downloading STM32CubeIDE (4 min) Installation-Windows (moins d'1 min) Installation-Ubuntu (2 min) Embedded Target (3 min) Documents required (3 min) Creating Hello-World project (10 min) | E6: =SUMIFS(Leçons!$E$5:$E$289,Leçons!$F$5:$F$289,A6) -> 32.74 | F6: Réécrire en C++ : Installer l'environnement et rassembler la datasheet et le reference manual | G6: namespace, références, const, std::array, extern "C" | K6: =IF(AND(I6="Oui",OR(E6=0,H6="Oui")),"Oui","")
A7: 46308 | B7: J0 Fondations | C7: Vidéo + code | D7: SWV working principle (9 min) Testing Hello-World through SWV (6 min) OpenOCD and Semihosting to use printf (6 min) Debugging options (5 min) Single stepping (10 min) | E7: =SUMIFS(Leçons!$E$5:$E$289,Leçons!$F$5:$F$289,A7) -> 35.85 | F7: Réécrire en C++ : Créer le projet C++ (CubeIDE), faire marcher printf via SWV, comprendre extern "C" et le startup | G7: namespace, références, const, std::array, extern "C" | K7: =IF(AND(I7="Oui",OR(E7=0,H7="Oui")),"Oui","")
A8: 46309 | B8: J0 Fondations | C8: Vidéo + code | D8: Disassembly and Register windows (4 min) Breakpoints (6 min) Expression and variable windows (5 min) Memory browser windows (8 min) Call stack and fault analyzers (7 min) Data watch-points (5 min) | E8: =SUMIFS(Leçons!$E$5:$E$289,Leçons!$F$5:$F$289,A8) -> 34.48 | F8: Réécrire en C++ : Programme de tri en C++ (std::array) puis breakpoints, watchpoints, fenêtre SFR, fault analyzer | G8: namespace, références, const, std::array, extern "C" | K8: =IF(AND(I8="Oui",OR(E8=0,H8="Oui")),"Oui","")
A9: 46310 | B9: J0 Fondations | C9: Vidéo + code | D9: SFR windows (5 min) Other basic features of IDE (5 min) Understanding Memory Map of the MCU: Part 1 (5 min) Understanding Memory Map of the MCU: Part 2 (3 min) Understanding Memory Map of the MCU: Part 3 (9 min) Test your understanding (quiz) MCU Bus Interfaces Explanation Part 1: I-Code/D-Code/S-Bus (13 min) | E9: =SUMIFS(Leçons!$E$5:$E$289,Leçons!$F$5:$F$289,A9) -> 39.79 | F9: Réécrire en C++ : Header C++ avec les adresses de base de la carte mémoire (constexpr) | G9: constexpr, enum class | K9: =IF(AND(I9="Oui",OR(E9=0,H9="Oui")),"Oui","")
A10: 46311 | B10: J0 Fondations | C10: Vidéo + code | D10: MCU Bus Interfaces Explanation Part 2: AHB/APB1/APB2 (8 min) MCU Bus Interfaces Explanation Part 3: Q/A session (11 min) Understanding MCU Bus Matrix (6 min) Test your understanding (quiz) Understanding MCU Clocking System:Part1 (6 min) | E10: =SUMIFS(Leçons!$E$5:$E$289,Leçons!$F$5:$F$289,A10) -> 31.92 | F10: Réécrire en C++ : Noter dans ton header quel périphérique est sur quel bus (AHB1, APB1, APB2) | G10: constexpr, enum class | K10: =IF(AND(I10="Oui",OR(E10=0,H10="Oui")),"Oui","")
A11: 46314 | B11: J0 Fondations | C11: Vidéo + code | D11: Understanding MCU clock sources and HSE (11 min) HSI and RCC registers (11 min) Peripheral clock configuration (13 min) | E11: =SUMIFS(Leçons!$E$5:$E$289,Leçons!$F$5:$F$289,A11) -> 35.12 | F11: Réécrire en C++ : Classe Rcc : activer les horloges, sortir HSI puis HSE sur MCO1 (PA8) et mesurer | G11: enum class, constexpr, volatile, name mangling | K11: =IF(AND(I11="Oui",OR(E11=0,H11="Oui")),"Oui","")
A12: 46315 | B12: J0 Fondations | C12: Vidéo + code | D12: Exercise : HSI measurements (9 min) About USB logic analyzer (5 min) Code implementation (12 min) Exercise : HSE measurements (9 min) | E12: =SUMIFS(Leçons!$E$5:$E$289,Leçons!$F$5:$F$289,A12) -> 34.79 | F12: Réécrire en C++ : Classe Rcc : activer les horloges, sortir HSI puis HSE sur MCO1 (PA8) et mesurer | G12: enum class, constexpr, volatile, name mangling | K12: =IF(AND(I12="Oui",OR(E12=0,H12="Oui")),"Oui","")
A13: 46316 | B13: J0 Fondations | C13: Vidéo + code | D13: Understanding MCU Vector Table (24 min) Understanding MCU interrupt Design , NVIC, Interrupt handling: Part 1 (10 min) | E13: =SUMIFS(Leçons!$E$5:$E$289,Leçons!$F$5:$F$289,A13) -> 34.23 | F13: Réécrire en C++ : Handler d'interruption en extern "C", lire la table des vecteurs, activer une IRQ dans le NVIC | G13: enum class, constexpr, volatile, name mangling | K13: =IF(AND(I13="Oui",OR(E13=0,H13="Oui")),"Oui","")
A14: 46317 | B14: J0 Fondations | C14: Vidéo + code | D14: Understanding MCU interrupt Design , NVIC, Interrupt handling: Part 2 (7 min) Understanding MCU interrupt Design , NVIC, Interrupt handling: Part 3 (14 min) Importance of "Volatile" Keyword: Part-1 (10 min) Importance of "Volatile" Keyword-Part 2 (8 min) | E14: =SUMIFS(Leçons!$E$5:$E$289,Leçons!$F$5:$F$289,A14) -> 37.65 | F14: Réécrire en C++ : Handler d'interruption en extern "C", lire la table des vecteurs, activer une IRQ dans le NVIC | G14: enum class, constexpr, volatile, name mangling | K14: =IF(AND(I14="Oui",OR(E14=0,H14="Oui")),"Oui","")
A15: 46318 | B15: J0 Fondations | C15: Vidéo + code | D15: GPIO pin and GPIO port (2 min) GPIO behind the scene (3 min) GPIO input mode with high impedance state (1 min) GPIO input mode with pull-up/down state (1 min) GPIO output mode with open drain state (6 min) GPIO output mode with push pull state (3 min) Optimizing I/O power consumption (3 min) Test your understanding (quiz) GPIO programming structure (3 min) Exploring GPIO PORT and pins of STM32F4xx Discovery board (moins d'1 min) GPIO Mode register(used to set mode for a pin) (6 min) | E15: =SUMIFS(Leçons!$E$5:$E$289,Leçons!$F$5:$F$289,A15) -> 28.99 | F15: Réécrire en C++ : Fiche de révision : push-pull, open-drain, pull-up et pull-down | G15: Constructeur/destructeur, RAII, encapsulation | K15: =IF(AND(I15="Oui",OR(E15=0,H15="Oui")),"Oui","")
A16: 46321 | B16: J0 Fondations | C16: Vidéo + code | D16: Input configuration of a Microcontroller's GPIO Pin (12 min) Output Configuration of a GPIO Pin in Push pull mode (3 min) Output Configuration of a GPIO Pin in open drain mode (5 min) Input stage of a GPIO pin during output configuration (moins d'1 min) Alternate functionality Configuration of a GPIO pin (3 min) GPIO out put type register explanation (1 min) GPIO output speed register and its applicability (6 min) GPIO Pull up and Pull down register (moins d'1 min) | E16: =SUMIFS(Leçons!$E$5:$E$289,Leçons!$F$5:$F$289,A16) -> 30.34 | F16: Réécrire en C++ : Struct de registres GPIO (volatile) et configuration d'une broche à la main | G16: Constructeur/destructeur, RAII, encapsulation | K16: =IF(AND(I16="Oui",OR(E16=0,H16="Oui")),"Oui","")
A17: 46322 | B17: J0 Fondations | C17: Vidéo + code | D17: GPIO input data register (1 min) GPIO output data register and summary of various modes discussed (2 min) Alternate functionality settings of a GPIO pin with example : Part 1 (5 min) Alternate functionality settings of a GPIO pin with example : Part 1 (6 min) Request for Review (moins d'1 min) Find Out I/O Alt Functionality (quiz) Test your understanding (quiz) Test your understanding (quiz) Enabling and disabling GPIO peripheral clock (1 min) GPIO driver development overview (4 min) MCU Specific header file and its contents (2 min) New project creation and creating MCU specific headerfile (4 min) Include path settings (2 min) Important note on IDE usage (moins d'1 min) Writing base address C macros for MCU's embedded memories : Part 1 (4 min) | E17: =SUMIFS(Leçons!$E$5:$E$289,Leçons!$F$5:$F$289,A17) -> 32.61 | F17: Réécrire en C++ : Classe Gpio : config (struct + enum class), constructeur qui active l'horloge, read, write, toggle | G17: Constructeur/destructeur, RAII, encapsulation | K17: =IF(AND(I17="Oui",OR(E17=0,H17="Oui")),"Oui","")
... A27: 46336 | B27: J0 Fondations | C27: Vidéo + code | D27: Logic levels (17 min) | E27: =SUMIFS(Leçons!$E$5:$E$289,Leçons!$F$5:$F$289,A27) -> 16.92 | F27: Réécrire en C++ : Fiche : courants max et niveaux logiques de la Nucleo (câblage GPS, IMU, SD) | G27: Pointeurs de fonction, membres static, lambdas sans capture | K27: =IF(AND(I27="Oui",OR(E27=0,H27="Oui")),"Oui","")
A28: 46337 | B28: J0 Fondations | C28: Code seul | E28: =SUMIFS(Leçons!$E$5:$E$289,Leçons!$F$5:$F$289,A28) -> 0 | F28: Bilan J0 : nettoie le dépôt (Rcc, Gpio, bouton), écris le README, commit, et relis ce que tu ne sais pas expliquer | G28: Révision : tout ce qui précède | K28: =IF(AND(I28="Oui",OR(E28=0,H28="Oui")),"Oui","")
A29: 46338 | B29: J0 Fondations | C29: Marge | E29: =SUMIFS(Leçons!$E$5:$E$289,Leçons!$F$5:$F$289,A29) -> 0 | F29: Jour de marge : rattrape ce qui n'est pas encore validé, ou avance sur la suite. | K29: =IF(AND(I29="Oui",OR(E29=0,H29="Oui")),"Oui","")
A30: 46339 | B30: J1 GPS | C30: Vidéo + code | D30: Intro UART vs USART (3 min) Understanding UART pins (3 min) UART frame formats (2 min) Baud Rate (2 min) Synchronization bits (1 min) UART Parity (4 min) Exploring UART functional block (2 min) UART peripheral clock (2 min) UART Transmitter (3 min) Uart Receiver (4 min) UART Start bit Detection (quiz) USART driver development confiugrable items (5 min) | E30: =SUMIFS(Leçons!$E$5:$E$289,Leçons!$F$5:$F$289,A30) -> 32.37 | F30: Réécrire en C++ : Schéma d'une trame UART, calcul du baud rate à la main | G30: string_view, enum class, RingBuffer<T, N> (templates) | K30: =IF(AND(I30="Oui",OR(E30=0,H30="Oui")),"Oui","")
A31: 46342 | B31: J1 GPS | C31: Vidéo + code | D31: USART driver APIs prototypes (2 min) Configuration options and USART registers (10 min) USART Driver API : USART Init (2 min) USART Driver API : Tx and Rx assignment (1 min) USART Driver API : Send data (5 min) USART oversampling (7 min) USART Baud rate calculation Part-2 (8 min) | E31: =SUMIFS(Leçons!$E$5:$E$289,Leçons!$F$5:$F$289,A31) -> 36.29 | F31: Réécrire en C++ : Classe Uart : init, envoi, baud rate en constexpr, test avec le PC | G31: string_view, enum class, RingBuffer<T, N> (templates) | K31: =IF(AND(I31="Oui",OR(E31=0,H31="Oui")),"Oui","")
A32: 46343 | B32: J1 GPS | C32: Vidéo + code | D32: USART Baud rate calculation Part-2 (4 min) USART baudrate coding (6 min) Exercise : USART send data to arduino (17 min) communicating with PC over UART (4 min) | E32: =SUMIFS(Leçons!$E$5:$E$289,Leçons!$F$5:$F$289,A32) -> 30.77 | F32: Réécrire en C++ : Classe Uart : init, envoi, baud rate en constexpr, test avec le PC | G32: string_view, enum class, RingBuffer<T, N> (templates) | K32: =IF(AND(I32="Oui",OR(E32=0,H32="Oui")),"Oui","")
A33: 46344 | B33: J1 GPS | C33: Vidéo + code | D33: USART interrupt discussion (3 min) Exercise (3 min) USART IRQ handler implementation : Assignment (moins d'1 min) | E33: =SUMIFS(Leçons!$E$5:$E$289,Leçons!$F$5:$F$289,A33) -> 6.48 | F33: Réécrire en C++ : Classe Uart : init, envoi, baud rate en constexpr, test avec le PC | G33: string_view, enum class, RingBuffer<T, N> (templates) | K33: =IF(AND(I33="Oui",OR(E33=0,H33="Oui")),"Oui","")
A34: 46345 | B34: J1 GPS | C34: Code seul | E34: =SUMIFS(Leçons!$E$5:$E$289,Leçons!$F$5:$F$289,A34) -> 0 | F34: Uart : réception par interruption dans un buffer circulaire (template RingBuffer<T, N>) | G34: string_view, machine à états, RingBuffer<T, N> | K34: =IF(AND(I34="Oui",OR(E34=0,H34="Oui")),"Oui","")
A35: 46346 | B35: J1 GPS | C35: Code seul | E35: =SUMIFS(Leçons!$E$5:$E$289,Leçons!$F$5:$F$289,A35) -> 0 | F35: Câbler le GPS et afficher les trames brutes sur le terminal du PC | G35: string_view, machine à états, RingBuffer<T, N> | K35: =IF(AND(I35="Oui",OR(E35=0,H35="Oui")),"Oui","")
A36: 46349 | B36: J1 GPS | C36: Code seul | E36: =SUMIFS(Leçons!$E$5:$E$289,Leçons!$F$5:$F$289,A36) -> 0 | F36: Parseur NMEA : trame RMC (heure, position, vitesse) avec vérification du checksum | G36: string_view, machine à états, RingBuffer<T, N> | K36: =IF(AND(I36="Oui",OR(E36=0,H36="Oui")),"Oui","")
A37: 46350 | B37: J1 GPS | C37: Code seul | E37: =SUMIFS(Leçons!$E$5:$E$289,Leçons!$F$5:$F$289,A37) -> 0 | F37: Parseur NMEA : trame GGA (fix, satellites) et gestion des trames incomplètes | G37: string_view, machine à états, RingBuffer<T, N> | K37: =IF(AND(I37="Oui",OR(E37=0,H37="Oui")),"Oui","")
A38: 46351 | B38: J1 GPS | C38: Code seul | E38: =SUMIFS(Leçons!$E$5:$E$289,Leçons!$F$5:$F$289,A38) -> 0 | F38: Régler la fréquence du GPS (10 Hz si le module le permet) et mesurer la fréquence réelle | G38: string_view, machine à états, RingBuffer<T, N> | K38: =IF(AND(I38="Oui",OR(E38=0,H38="Oui")),"Oui","")
A39: 46352 | B39: J1 GPS | C39: Code seul | E39: =SUMIFS(Leçons!$E$5:$E$289,Leçons!$F$5:$F$289,A39) -> 0 | F39: Test en extérieur, nettoyage, README et validation du jalon 1 | G39: string_view, machine à états, RingBuffer<T, N> | K39: =IF(AND(I39="Oui",OR(E39=0,H39="Oui")),"Oui","")
A40: 46353 | B40: J1 GPS | C40: Marge | E40: =SUMIFS(Leçons!$E$5:$E$289,Leçons!$F$5:$F$289,A40) -> 0 | F40: Jour de marge : rattrape ce qui n'est pas encore validé, ou avance sur la suite. | K40: =IF(AND(I40="Oui",OR(E40=0,H40="Oui")),"Oui","")
A41: 46356 | B41: J2 Carte SD | C41: Vidéo + code | D41: Introduction to SPI Bus (6 min) SPI comparison with other protocols (4 min) Importance of SPI slave select pin (2 min) SPI Minimum bus configuration (2 min) SPI behind the scene data communication principle (4 min) SPI bus configuration discussion : full duplex, half duplex and simplex (6 min) SPI functional block diagram explanation (7 min) | E41: =SUMIFS(Leçons!$E$5:$E$289,Leçons!$F$5:$F$289,A41) -> 31.75 | F41: Réécrire en C++ : Fiche CPOL/CPHA avec chronogrammes, câblage SPI de la Nucleo | G41: Surcharge de méthodes, const, std::span (C++20) | K41: =IF(AND(I41="Oui",OR(E41=0,H41="Oui")),"Oui","")
A42: 46357 | B42: J2 Carte SD | C42: Vidéo + code | D42: NSS settings in STM32 master and slave modes (3 min) STM32 SPI hardware and software slave managements (6 min) SPI CPOL and CPHA discussion (12 min) SPI CPOL and CPHA waveform example (8 min) SPI peripherals of your Microcontroller (1 min) | E42: =SUMIFS(Leçons!$E$5:$E$289,Leçons!$F$5:$F$289,A42) -> 30.47 | F42: Réécrire en C++ : Fiche CPOL/CPHA avec chronogrammes, câblage SPI de la Nucleo | G42: Surcharge de méthodes, const, std::span (C++20) | K42: =IF(AND(I42="Oui",OR(E42=0,H42="Oui")),"Oui","")
A43: 46358 | B43: J2 Carte SD | C43: Vidéo + code | D43: SPI Serial clock frequency (5 min) SPI API requirements and configuration items (7 min) updating MCU specific header file with SPI related details (2 min) SPI adding API prototypes to driver header file (5 min) Implementation of SPI peripheral clock control API (4 min) | E43: =SUMIFS(Leçons!$E$5:$E$289,Leçons!$F$5:$F$289,A43) -> 23.5 | F43: Réécrire en C++ : Classe Spi : config, constructeur, horloge, envoi | G43: Surcharge de méthodes, const, std::span (C++20) | K43: =IF(AND(I43="Oui",OR(E43=0,H43="Oui")),"Oui","")
A44: 46359 | B44: J2 Carte SD | C44: Vidéo + code | D44: SPI user configuration options writing and register bit definition macros (18 min) Implementation of SPI init API : Part 1 (3 min) Implementation of SPI init API : Part 2 (4 min) Implementation of SPI send data API : Part 1 (8 min) | E44: =SUMIFS(Leçons!$E$5:$E$289,Leçons!$F$5:$F$289,A44) -> 33.45 | F44: Réécrire en C++ : Classe Spi : config, constructeur, horloge, envoi | G44: Surcharge de méthodes, const, std::span (C++20) | K44: =IF(AND(I44="Oui",OR(E44=0,H44="Oui")),"Oui","")
A45: 46360 | B45: J2 Carte SD | C45: Vidéo + code | D45: Implementation of SPI send data API : Part 2 (5 min) Implementation of SPI send data API : Part 3 (6 min) Implementation of SPI send data API : Part 4 (1 min) Exercise to test SPI Send Data API (2 min) Finding out microcontroller pins to communicate over SPI2 (4 min) Exercise : Code implementation : Part 1 (4 min) Exercise : Code implementation : Part 2 (7 min) Exercise : Code implementation : Part 3 (6 min) | E45: =SUMIFS(Leçons!$E$5:$E$289,Leçons!$F$5:$F$289,A45) -> 34.9 | F45: Réécrire en C++ : Envoi vers l'Arduino, vérification à l'analyseur logique | G45: Surcharge de méthodes, const, std::span (C++20) | K45: =IF(AND(I45="Oui",OR(E45=0,H45="Oui")),"Oui","")
A46: 46363 | B46: J2 Carte SD | C46: Vidéo + code | D46: Exercise : Testing (15 min) Exercise : Communicating with Arduino slave (12 min) Exercise : Coding Part 1 (7 min) | E46: =SUMIFS(Leçons!$E$5:$E$289,Leçons!$F$5:$F$289,A46) -> 34.25 | F46: Réécrire en C++ : Envoi vers l'Arduino, vérification à l'analyseur logique | G46: Surcharge de méthodes, const, std::span (C++20) | K46: =IF(AND(I46="Oui",OR(E46=0,H46="Oui")),"Oui","")
A47: 46364 | B47: J2 Carte SD | C47: Vidéo + code | D47: Exercise : Coding Part 2 (3 min) Exercise : Coding Part 3 (4 min) Exercise : Testing (7 min) Implementation of SPI data receive API : Part 1 (2 min) Implementation of SPI data receive API : Part 2 (2 min) Exercise : SPI command and response based communication (8 min) Exercise : Coding Part 1 (10 min) | E47: =SUMIFS(Leçons!$E$5:$E$289,Leçons!$F$5:$F$289,A47) -> 36.3 | F47: Réécrire en C++ : Réception SPI et protocole commande/réponse | G47: enum class pour une machine à états, callbacks | K47: =IF(AND(I47="Oui",OR(E47=0,H47="Oui")),"Oui","")
A48: 46365 | B48: J2 Carte SD | C48: Vidéo + code | D48: Exercise : Coding Part 2 (9 min) Exercise : Coding Part 3 (14 min) SPI peripheral interrupting the processor (7 min) SPI interrupt mode API implementation and changes to handle structure (5 min) | E48: =SUMIFS(Leçons!$E$5:$E$289,Leçons!$F$5:$F$289,A48) -> 34.54 | F48: Réécrire en C++ : Réception SPI et protocole commande/réponse | G48: enum class pour une machine à états, callbacks | K48: =IF(AND(I48="Oui",OR(E48=0,H48="Oui")),"Oui","")
A49: 46366 | B49: J2 Carte SD | C49: Vidéo + code | D49: SPI send data with interrupt API implementation (5 min) SPI receive data with interrupt implementation (2 min) SPI : Handling of interrupts (4 min) SPI IRQ handler implementation : Part 1 (8 min) SPI IRQ handler implementation : Part 2 (9 min) SPI IRQ handler implementation : Part 3 (10 min) | E49: =SUMIFS(Leçons!$E$5:$E$289,Leçons!$F$5:$F$289,A49) -> 36.9 | F49: Réécrire en C++ : Version par interruption avec machine à états (enum class) | G49: enum class pour une machine à états, callbacks | K49: =IF(AND(I49="Oui",OR(E49=0,H49="Oui")),"Oui","")
A50: 46367 | B50: J2 Carte SD | C50: Vidéo + code | D50: Exercise (16 min) Common problems in SPI and Debugging Tips (6 min) | E50: =SUMIFS(Leçons!$E$5:$E$289,Leçons!$F$5:$F$289,A50) -> 22.06 | F50: Réécrire en C++ : Version par interruption avec machine à états (enum class) | G50: enum class pour une machine à états, callbacks | K50: =IF(AND(I50="Oui",OR(E50=0,H50="Oui")),"Oui","")
...

Sheet Leçons
A1: Leçons du cours dans le nouvel ordre
A2: Source : liste des leçons fournie par l'utilisateur (durées à vitesse normale, quiz sans durée). Les dates viennent du plan quotidien ; les leçons facultatives n'ont pas de date.
A4: N° | B4: Jalon | C4: Chapitre | D4: Leçon | E4: Durée (min) | F4: Date prévue
A5: 1 | B5: J0 Fondations | C5: Intro, présentation, installation, documents | D5: About the instructor | E5: 0.28 | F5: 46307
A6: 2 | B6: J0 Fondations | C6: Intro, présentation, installation, documents | D6: Important Note | E6: 0.72 | F6: 46307
A7: 3 | B7: J0 Fondations | C7: Intro, présentation, installation, documents | D7: What is this course all about ?? | E7: 5.95 | F7: 46307
A8: 4 | B8: J0 Fondations | C8: Intro, présentation, installation, documents | D8: Source Code and Slides | E8: 0.03 | F8: 46307
A9: 5 | B9: J0 Fondations | C9: Intro, présentation, installation, documents | D9: Rating and Review | E9: 0.53 | F9: 46307
A10: 6 | B10: J0 Fondations | C10: Intro, présentation, installation, documents | D10: About MCU Development board | E10: 3.45 | F10: 46307
A11: 7 | B11: J0 Fondations | C11: Intro, présentation, installation, documents | D11: Hardware/Software Requirements | E11: 0.08 | F11: 46307
A12: 8 | B12: J0 Fondations | C12: Intro, présentation, installation, documents | D12: Downloading STM32CubeIDE | E12: 3.55 | F12: 46307
A13: 9 | B13: J0 Fondations | C13: Intro, présentation, installation, documents | D13: Installation-Windows | E13: 0.72 | F13: 46307
A14: 10 | B14: J0 Fondations | C14: Intro, présentation, installation, documents | D14: Installation-Ubuntu | E14: 2.02 | F14: 46307
A15: 11 | B15: J0 Fondations | C15: Intro, présentation, installation, documents | D15: Embedded Target | E15: 2.8 | F15: 46307
A16: 12 | B16: J0 Fondations | C16: Intro, présentation, installation, documents | D16: Documents required | E16: 2.73 | F16: 46307
... A249: 245 | B249: J3 IMU | C249: I2C maître : réception | D249: Exercise : Testing repeated start | E249: 8.05 | F249: 46435
A250: 246 | B250: J4 Fusion + visualisation | C250: RTC DS1307 et SysTick | D250: RTC and Systick | E250: 12.57
A251: 247 | B251: Facultatif | C251: I2C en interruption, erreurs | D251: I2C IRQ and interrupt discussion | E251: 5.68
A252: 248 | B252: Facultatif | C252: I2C en interruption, erreurs | D252: I2C errors and importance of BUSY flag | E252: 8.82
A253: 249 | B253: Facultatif | C253: I2C en interruption, erreurs | D253: I2C handle structure modification | E253: 2.48
A254: 250 | B254: Facultatif | C254: I2C en interruption, erreurs | D254: I2C adding interrupt related macros and interrupt APIs | E254: 3.28
A255: 251 | B255: Facultatif | C255: I2C en interruption, erreurs | D255: Assignment : I2C interrupt APIs implementation | E255: 2.17
A256: 252 | B256: Facultatif | C256: I2C en interruption, erreurs | D256: Implementation of I2C interrupt based APIs | E256: 2.1
A257: 253 | B257: Facultatif | C257: I2C en interruption, erreurs | D257: I2C IRQ handler implementation Part 1 | E257: 8.68
A258: 254 | B258: Facultatif | C258: I2C en interruption, erreurs | D258: I2C IRQ handler implementation Part 2 | E258: 4.7
A259: 255 | B259: Facultatif | C259: I2C en interruption, erreurs | D259: I2C IRQ handler implementation Part 3 | E259: 8.17
A260: 256 | B260: Facultatif | C260: I2C en interruption, erreurs | D260: I2C IRQ handler implementation Part 4 | E260: 3.12
A261: 257 | B261: Facultatif | C261: I2C en interruption, erreurs | D261: I2C IRQ handler implementation Part 5 | E261: 3.9
... A289: 285 | B289: Facultatif | C289: LCD | D289: Testing | E289: 0
D290: Total (min) | E290: =SUM(E5:E289) -> 1694.58
D291: Total (h) | E291: =E290/60 -> 28.243
